Workbook

Sheet 1. Sign Off & Other Checks
C2: Client Money Reconciliations Sign Off | D2: ='2. Daily Client Money Report'!B4 -> 46189
C4: Internal Reconciliation CISA & LISA | G4: Negative Balance check
C5: Checks | D5: Inputter | E5: Checker | G5: Check to ensure no user has a negative balance
C6: Update underlying Workings tabs | E6: LK | G6: Looker: | H6: Explore Tax Wrapper Money Flows & Balances
C7: Combined User Balance from Ledger vs Bulk Plum Ledger Balance for reconcilation date has been updated | D7: DB | G7: Screenshot of report
C8: External Ledger balance matches that of Plum Ledger balance on Internal workings tab | D8: DB
C9: Reconciliation difference at 0 | D9: DB
C10: All adjustments have relevant commentary and explaination | D10: DB
C11: All breaks have relevant details (user ID, order ID, explanation) | D11: DB
C12: Negative Balance check | D12: DB
C13: Check all cells are mapped correctly to workings | D13: DB
C14: Add comments for any signficant changes or omissions | D14: DB
C15: Update the overall conclusion on Daily CM report | D15: DB
C16: Final sign off
G17: No negative balances
C19: External Reconciliation CISA & LISA
C20: Check | D20: Inputter | E20: Checker
C21: Update underlying Working tabs | E21: LK
C22: External balances (Citi, Lloyds, HSBC, QNB cash) updated | D22: DB
C23: Reconciliation difference at 0 | D23: DB
C24: All adjustments have relevant commentary and explaination | D24: DB
C25: All breaks have relevant details (transaction ID, order ID, explanation) | D25: DB
C26: CASS Internal Reconciliation tab
C27: Check all cells are mapped correctly to workings | D27: DB
C28: Add comments for any signficant changes or omissions | D28: DB
C29: Update the overall conclusion | D29: DB
C30: Final sign off
C32: Unalloc Account Reconciled
C33: Check | D33: Inputter | E33: Checker
C34: Unalloc holdings accounted for | D34: DB | E34: LK | G34: ="Negative balance from the " &TEXT(D2, "dd/mm") -> Negative balance from the 16/06
C35: 10 day check | D35: DB | G35: Number | H35: Date | I35: User ID | J35: Subscription ID | K35: Product name | L35: Subscription status | M35: Balance | N35: Notes
C37: Manual combined user balace check | L37: Total | M37: =SUM(M36) -> 0
L38: Difference to prev day | M38: =M46-M37 -> 0
C39: Combined User Balance Check - CISA | D39: Amounts
C40: Internal CUB from previous day | D40: ='5. CISA Internal Workings'!F19 -> 2386124298
C41: Debits (Recon data) from Rec data | D41: 10417421
C42: Credits (Recon data) from Rec data | D42: 11826163
C43: Total | D43: =D40-D41+D42 -> 2387533039 | G43: ="Negative balance from the " & TEXT(IF(WEEKDAY(D2)=2, D2-3, D2-1), "dd/mm") -> Negative balance from the 15/06
G44: Number | H44: Date | I44: User ID | J44: Subscription ID | K44: Product name | L44: Subscription status | M44: Balance | N44: Notes
C45: Internal CUB from Rec Date | D45: ='5. CISA Internal Workings'!F18 -> 2387533039
...

Sheet 2. Daily Client Money Report
A1: Saveable Daily Client Money and Asset Reporting
A4: Close of Business Date | B4: ='4. CISA - CASS Internal Rec'!E4 -> 46189
A6: Cash ISA Client Money Balances - GBP
A7: Bank | B7: Account | C7: Previous Day Balance | D7: COB Balance | E7: Variance | F7: Entity
A8: Citi Bank NA London | B8: Saveable Cash ISA UK Client Money (14747801) | C8: ='7. CISA External Workings'!I31 -> 1.7699286e+08 | D8: ='7. CISA External Workings'!I30 -> 1.7602115e+08 | E8: =D8-C8 -> -971703.8 | F8: Saveable Limited
A9: Lloyds Bank Plc | B9: Saveable Cash ISA Client Account (27551460) | C9: ='7. CISA External Workings'!I36 -> 3959844.1 | D9: ='7. CISA External Workings'!I35 -> 3959844.1 | E9: =D9-C9 -> 0 | F9: Saveable Limited
A10: Lloyds Bank Plc | B10: Saveable Cash ISA 30D Notice Client Account (27571468) | C10: ='7. CISA External Workings'!I41 -> 747535672 | D10: ='7. CISA External Workings'!I40 -> 747535672 | E10: =D10-C10 -> 0 | F10: Saveable Limited
A11: QNB | B11: Qatar National Bank (4311-000545-310) | C11: ='7. CISA External Workings'!I46 -> 1168000000 | D11: ='7. CISA External Workings'!I45 -> 1168000000 | E11: =D11-C11 -> 0 | F11: Saveable Limited
A12: BlackRock QMMF | B12: Blackrock QMMF | C12: ='7. CISA External Workings'!I56 -> 0 | D12: ='7. CISA External Workings'!I55 -> 0 | E12: =D12-C12 -> 0 | F12: Saveable Limited
A13: BBVA | B13: BBVA Easy access (01778650) | C13: ='7. CISA External Workings'!I61 -> 2.9496063e+08 | D13: ='7. CISA External Workings'!I60 -> 2.9496063e+08 | E13: =D13-C13 -> 0 | F13: Saveable Limited
A14: BBVA | B14: BBVA Notice account (06758170) | C14: ='7. CISA External Workings'!I66 -> 0 | D14: ='7. CISA External Workings'!I65 -> 0 | E14: =D14-C14 -> 0 | F14: Saveable Limited
A15: Clydesdale Bank PLC TA Virgin Money | B15: Saveable Cash ISA 95 Day Notice (12204224) | C15: ='7. CISA External Workings'!I71 -> 0 | D15: ='7. CISA External Workings'!I70 -> 0 | E15: =D15-C15 -> 0 | F15: Saveable Limited
A16: Clydesdale Bank PLC TA Virgin Money | B16: Saveable Cash ISA 65 Day Notice (12204316) | C16: ='7. CISA External Workings'!I76 -> 0 | D16: ='7. CISA External Workings'!I75 -> 0 | E16: =D16-C16 -> 0 | F16: Saveable Limited
A17: Clydesdale Bank PLC TA Virgin Money | B17: Saveable Cash ISA 30 Day Notice (12204161) | C17: ='7. CISA External Workings'!I81 -> 0 | D17: ='7. CISA External Workings'!I80 -> 0 | E17: =D17-C17 -> 0 | F17: Saveable Limited
A18: Clydesdale Bank PLC TA Virgin Money | B18: Saveable Cash ISA Instant access (12204414) | C18: ='7. CISA External Workings'!I86 -> 0 | D18: ='7. CISA External Workings'!I85 -> 0 | E18: =D18-C18 -> 0 | F18: Saveable Limited
A19: JP Morgan | B19: JP Morgan Client Money account (76919500) | C19: ='7. CISA External Workings'!I91 -> 0 | D19: ='7. CISA External Workings'!I90 -> 0 | E19: =D19-C19 -> 0 | F19: Saveable Limited
B20: Total | C20: =SUM(C8:C19) -> 2391449004 | D20: =SUM(D8:D19) -> 2390477301
D22: CISA Net Increase/decrease | E22: =SUM(E8:E19) -> -971703.8
A24: Lifetime ISA Client Money Balances - GBP
A25: Bank | B25: Account | C25: Previous Day Balance | D25: COB Balance | E25: Variance | F25: Entity
A26: CitiBank NA London | B26: Saveable Lifetime ISA UK Client Money (15242487) | C26: ='12. LISA External Workings'!I31 -> 38363170 | D26: ='12. LISA External Workings'!I30 -> 38973579 | E26: =D26-C26 -> 610408.97 | F26: Saveable Limited
A27: Lloyds Bank Plc | B27: Saveable Lifetime ISA Client Account (27561260) | C27: ='12. LISA External Workings'!I36 -> 714980.29 | D27: ='12. LISA External Workings'!I35 -> 714980.29 | E27: =D27-C27 -> 0 | F27: Saveable Limited
A28: Lloyds Bank Plc | B28: Saveable Lifetime ISA 30D Notice Client Account (27571060) | C28: ='12. LISA External Workings'!I41 -> 79300000 | D28: ='12. LISA External Workings'!I40 -> 79300000 | E28: =D28-C28 -> 0 | F28: Saveable Limited
A29: QNB | B29: Qatar National Bank (4311-000545-311) | C29: ='12. LISA External Workings'!I46 -> 100000000 | D29: ='12. LISA External Workings'!I45 -> 100000000 | E29: =D29-C29 -> 0 | F29: Saveable Limited
B30: Total | C30: =SUM(C26:C29) -> 2.1837815e+08 | D30: =SUM(D26:D29) -> 2.1898856e+08
D32: LISA Net Increase/decrease | E32: =SUM(E26:E29) -> 610408.97
D34: Total ISA increase/decrease | E34: =E22+E32 -> -361294.83
A37: Cash ISA | D37: Lifetime ISA
A38: Commentary on Variances | D38: Commentary on Variances
A39: Citibank *This account is used for user transfers, deposits and withdrawals | B39: N/A | D39: Citibank *This account is used for user transfers, deposits and withdrawals | E39: N/A
A40: Lloyds EA | B40: N/A | D40: Lloyds EA | E40: N/A
A41: Lloyds Notice | B41: N/A | D41: Lloyds Notice | E41: N/A
A42: QNB | B42: N/A | D42: QNB | E42: N/A
A43: BBVA | B43: N/A
A46: Daily Reconciliation
A47: Requirement | B47: ='5. CISA Internal Workings'!F42+'10. LISA Internal Workings'!F46 +B66 -> 2609495399
A48: Inclusive of transfers in to apply | B48: ='5. CISA Internal Workings'!M53+'10. LISA Internal Workings'!M57 -> 3507294.7
A49: Total Requirement (inclusive of Quai) | B49: =B47+B48 -> 2613002694
A50: Resource (inclusive of Quai) | B50: ='7. CISA External Workings'!O24+'12. LISA External Workings'!K21 +B67 -> 2612998057
A51: Shortfall / Surplus (inclusive of Quai) | B51: =B50-B49 +B68 -> -4636.9443
...

Sheet 3. Unalloc Rec
B2: UNALLOC Balance | E2: Date: | F2: ='4. CISA - CASS Internal Rec'!E4 -> 46189 | J2: Unallocated Cash Review
C3: Client money temporarily held in our Unalloc account | K3: Value | L3: Tolerance
C4: These amounts count towards the 'Combined User Balance' in the Internal Rec | J4: CISA total unallocated | K4: =M18 -> 294085.7 | L4: {=IF(K4<(0.00025*INDIRECT("'2. Daily Client Money Report'!D20")), "Total amount is within the overall tolerance level (0.025%)", "Total amount is above the overall tolerance level (0.025%)")} -> Total amount is within the overall tolerance level (0.025%)
C5: Note: Client money must be allocated in 10 business days | J5: LISA total unallocated | K5: =M47 -> 163659.42 | L5: {=IF(K5<(0.00025*INDIRECT("'2. Daily Client Money Report'!D30")), "Total amount is within the overall tolerance level (0.025%)", "Total amount is above the overall tolerance level (0.025%)")} -> Total amount is above the overall tolerance level (0.025%)
J6: 0-2 days | K6: =SUMIFS(M:M, Q:Q, ">=0", Q:Q, "<=2") -> 350308.39
J7: 3-5 days | K7: =SUMIFS(M:M, Q:Q, ">=3", Q:Q, "<=5") -> 77906.5
J8: 6-9 days | K8: =SUMIFS(M:M, Q:Q, ">=6", Q:Q, "<=9") -> 26046.54
J9: 10+ days | K9: =SUMIFS(M:M, Q:Q, ">=10") -> 3483.69
B11: CISA
C13: Source: | D13: Explore Wealth Money Flows & Balances
C14: Live Unalloc sheet | D14: CISA Unalloc Ledger and Payins - Google Sheets
C16: Looker UNALLOC balance
C18: =F2 -> 46189 | D18: COB Balance according to Looker | L18: Looker Balance | M18: 294085.7
C21: CISA Money
C22: user_id | D22: ledger_entry_id | E22: ledger_entry_created_at | F22: ledger_entry_type | G22: ledger_entry_amount | H22: product | I22: subscription_id | J22: collection_id | K22: transaction_id | L22: provider_id | M22: payin_amount | N22: transaction_type | O22: payin_created_at | Q22: Days Aged | R22: Breach notes | S22: Commentary
C23: 73df5aae-f42a-49a0-9d8f-616ca6dbebaa | D23: 019eb1df-f256-71a1-b1ce-7c7ae8b244bc | E23: 46183.591 | F23: credit | G23: 29997.68 | H23: cash_isa | I23: 9bc00e6b-ce5f-48c5-ae3a-1baabe00f337 | J23: e3a86178-e782-4b8e-a5af-c71a91f91e51 | K23: e3a86178-e782-4b8e-a5af-c71a91f91e51 | L23: 400250 51421336-2136136478 | M23: 29997.68 | N23: payin | O23: 46182.226 | Q23: =NETWORKDAYS(E23, TODAY())-1 -> 5 | R23: 26-PLU-126 - CISA | S23: N/A
C24: 73df5aae-f42a-49a0-9d8f-616ca6dbebaa | D24: 019eb6b9-c0a2-7317-ab4a-c235d039858e | E24: 46184.533 | F24: credit | G24: 18184.43 | H24: cash_isa | I24: 9bc00e6b-ce5f-48c5-ae3a-1baabe00f337 | J24: 8a36818d-cb4b-4b51-98cd-feffaecfad30 | K24: 8a36818d-cb4b-4b51-98cd-feffaecfad30 | L24: 13267202-51989231 | M24: 18184.43 | N24: payin | O24: 46183.169 | Q24: =NETWORKDAYS(E24, TODAY())-1 -> 4 | R24: N/A | S24: N/A
C25: 73df5aae-f42a-49a0-9d8f-616ca6dbebaa | D25: 019ecb64-c843-7d12-81ee-f6401245704f | E25: 46188.547 | F25: credit | G25: 64323.37 | H25: cash_isa | I25: 9bc00e6b-ce5f-48c5-ae3a-1baabe00f337 | J25: 79376e9a-a2d9-4da6-80da-2fccb69993e9 | K25: 79376e9a-a2d9-4da6-80da-2fccb69993e9 | L25: NOREF-878813225 | M25: 64323.37 | N25: payin | O25: 46185.086 | Q25: =NETWORKDAYS(E25, TODAY())-1 -> 2 | R25: N/A | S25: N/A
C26: 73df5aae-f42a-49a0-9d8f-616ca6dbebaa | D26: 019ecb64-c733-7ae4-944c-db2cb0274f72 | E26: 46188.547 | F26: credit | G26: 40492.94 | H26: cash_isa | I26: 9bc00e6b-ce5f-48c5-ae3a-1baabe00f337 | J26: d1610b83-cb8b-45f0-bea4-69fec40f5e82 | K26: d1610b83-cb8b-45f0-bea4-69fec40f5e82 | L26: NOREF-1362020235 | M26: 40492.94 | N26: payin | O26: 46185.669 | Q26: =NETWORKDAYS(E26, TODAY())-1 -> 2 | R26: N/A | S26: N/A
C27: 73df5aae-f42a-49a0-9d8f-616ca6dbebaa | D27: 019ed024-854b-7377-878e-9bd25cd97072 | E27: 46189.469 | F27: credit | G27: 21471.6 | H27: cash_isa | I27: 9bc00e6b-ce5f-48c5-ae3a-1baabe00f337 | J27: 228cd2f5-1ee0-4962-a649-82c9f17961ae | K27: 228cd2f5-1ee0-4962-a649-82c9f17961ae | L27: WK648730Ba-580073357 | M27: 21471.6 | N27: payin | O27: 46188.669 | Q27: =NETWORKDAYS(E27, TODAY())-1 -> 1 | R27: N/A | S27: N/A
C28: 73df5aae-f42a-49a0-9d8f-616ca6dbebaa | D28: 019ed024-864c-78df-b53a-e34f6f766c49 | E28: 46189.469 | F28: credit | G28: 20974.52 | H28: cash_isa | I28: 9bc00e6b-ce5f-48c5-ae3a-1baabe00f337 | J28: 084ad475-9333-4dbe-8fb5-7d7b8ad84064 | K28: 084ad475-9333-4dbe-8fb5-7d7b8ad84064 | L28: NZ656284A-1098901635 | M28: 20974.52 | N28: payin | O28: 46188.669 | Q28: =NETWORKDAYS(E28, TODAY())-1 -> 1 | R28: N/A | S28: N/A
C29: 73df5aae-f42a-49a0-9d8f-616ca6dbebaa | D29: 019ed024-873d-7252-be6e-6e408eb5a4cb | E29: 46189.469 | F29: credit | G29: 20918.18 | H29: cash_isa | I29: 9bc00e6b-ce5f-48c5-ae3a-1baabe00f337 | J29: a7a2dae7-bd10-44fc-9b1b-25271dcf0442 | K29: a7a2dae7-bd10-44fc-9b1b-25271dcf0442 | L29: JX825895D-940686763 | M29: 20918.18 | N29: payin | O29: 46188.669 | Q29: =NETWORKDAYS(E29, TODAY())-1 -> 1 | R29: N/A | S29: N/A
C30: 73df5aae-f42a-49a0-9d8f-616ca6dbebaa | D30: 019ed024-8a33-7fb5-96a0-78ffd98b3516 | E30: 46189.469 | F30: credit | G30: 7.35 | H30: cash_isa | I30: 9bc00e6b-ce5f-48c5-ae3a-1baabe00f337 | J30: 42c3a58b-fec1-43e1-b86e-f071b829ba7a | K30: 42c3a58b-fec1-43e1-b86e-f071b829ba7a | L30: NOREF-910332414 | M30: 7.35 | N30: payin | O30: 46188.454 | Q30: =NETWORKDAYS(E30, TODAY())-1 -> 1 | R30: N/A | S30: N/A
C31: 73df5aae-f42a-49a0-9d8f-616ca6dbebaa | D31: 019ed024-88f1-789c-a803-e90f28c9087e | E31: 46189.469 | F31: credit | G31: 250 | H31: cash_isa | I31: 9bc00e6b-ce5f-48c5-ae3a-1baabe00f337 | J31: 5a92f897-6035-4172-9831-90028a8a98c2 | K31: 5a92f897-6035-4172-9831-90028a8a98c2 | L31: JC321715Da-518647334 | M31: 250 | N31: payin | O31: 46188.669 | Q31: =NETWORKDAYS(E31, TODAY())-1 -> 1 | R31: N/A | S31: N/A
C32: 73df5aae-f42a-49a0-9d8f-616ca6dbebaa | D32: 019ed024-8817-7d80-9685-39944e000a98 | E32: 46189.469 | F32: credit | G32: 42534.92 | H32: cash_isa | I32: 9bc00e6b-ce5f-48c5-ae3a-1baabe00f337 | J32: a50f2b4e-4ed2-48c6-ae8b-f3052f76d926 | K32: a50f2b4e-4ed2-48c6-ae8b-f3052f76d926 | L32: YM189882D-95846103 | M32: 42534.92 | N32: payin | O32: 46188.669 | Q32: =NETWORKDAYS(E32, TODAY())-1 -> 1 | R32: N/A | S32: N/A
C33: 73df5aae-f42a-49a0-9d8f-616ca6dbebaa | D33: 019ed0b1-3052-7f73-9d08-db917a292c59 | E33: 46189.576 | F33: credit | G33: 14930.71 | H33: cash_isa | I33: 9bc00e6b-ce5f-48c5-ae3a-1baabe00f337 | J33: 37db9098-7f00-401d-be6f-68777404753c | M33: 14930.71 | Q33: =NETWORKDAYS(E33, TODAY())-1 -> 1 | R33: N/A | S33: N/A
C34: 73df5aae-f42a-49a0-9d8f-616ca6dbebaa | D34: 019ed0fa-b1c2-7819-857e-40a98c4e3541 | E34: 46189.631 | F34: credit | G34: 20000 | H34: cash_isa | I34: 9bc00e6b-ce5f-48c5-ae3a-1baabe00f337 | J34: fc861623-56a0-47e2-bd62-7aa9db1633a8 | M34: 20000 | Q34: =NETWORKDAYS(E34, TODAY())-1 -> 1 | R34: N/A | S34: N/A
L35: Sum | M35: =sum(M23:M34) -> 294085.7
L38: Diff | M38: =M35-M18 -> 0
B40: LISA
C42: Source: | D42: Explore Wealth Money Flows & Balances
C43: Live Unalloc sheet | D43: CISA Unalloc Ledger and Payins - Google Sheets
C45: Looker UNALLOC balance
C47: =F2 -> 46189 | D47: COB Balance according to Looker | L47: Looker Balance | M47: 163659.42
C50: LISA Money
C51: user_id | D51: ledger_entry_id | E51: ledger_entry_created_at | F51: ledger_entry_type | G51: ledger_entry_amount | H51: product | I51: subscription_id | J51: collection_id | K51: transaction_id | L51: provider_id | M51: payin_amount | N51: transaction_type | O51: payin_created_at | Q51: Days Aged | R51: Breach notes | S51: Commentary
C52: 73df5aae-f42a-49a0-9d8f-616ca6dbebaa | D52: 0199816b-0e35-745a-bffb-2eb385b18f78 | E52: 45925.631 | F52: credit | G52: 25.82 | H52: lisa | I52: b7a59586-5d10-4989-91c2-f2376c7a6ab2 | J52: 8ecd675b-d3b5-4b51-9aee-fc2c558679b5 | M52: 25.82 | Q52: =NETWORKDAYS(E52, TODAY())-1 -> 189 | R52: Breach raised 09/10 - added to 25-PLU-079 | S52: Amount of 25.82 applies to HMRC gov bonus. Breach raised with engineering and product 09/10
C53: 73df5aae-f42a-49a0-9d8f-616ca6dbebaa | D53: 019a265f-0027-7d29-8ff1-8f39f64358c1 | E53: 45957.661 | F53: credit | G53: 39.36 | H53: lisa | I53: b7a59586-5d10-4989-91c2-f2376c7a6ab2 | J53: 7464d141-4aaa-46a8-ae96-c3c7997dfc03 | M53: 39.36 | Q53: =NETWORKDAYS(E53, TODAY())-1 -> 167 | R53: Breach raised 09/10 - added to 25-PLU-079 | S53: Amount of 39.36 applies to HMRC gov bonus. Breach raised with engineering and product 09/10
C54: 73df5aae-f42a-49a0-9d8f-616ca6dbebaa | D54: 019c0522-3a07-719b-bcbd-b2f0eb14e013 | E54: 46050.628 | F54: credit | G54: 1250.5 | H54: lisa | I54: b7a59586-5d10-4989-91c2-f2376c7a6ab2 | J54: 7464d141-4aaa-46a8-ae96-c3c7997dfc03 | M54: 1250.5 | Q54: =NETWORKDAYS(E54, TODAY())-1 -> 100 | R54: Breach raised 09/10 - added to 25-PLU-079 | S54: Amount of 1,250.50 applies to HMRC gov bonus. Breach raised with engineering and product 09/10
C55: 73df5aae-f42a-49a0-9d8f-616ca6dbebaa | D55: 019c9e6e-9ac8-7b3e-a27b-af919f6932b8 | E55: 46080.395 | F55: credit | G55: 2509.51 | H55: lisa | I55: b7a59586-5d10-4989-91c2-f2376c7a6ab2 | J55: 7464d141-4aaa-46a8-ae96-c3c7997dfc03 | M55: 2168.01 | Q55: =NETWORKDAYS(E55, TODAY())-1 -> 78 | R55: Breach raised 09/10 - added to 25-PLU-079 | S55: - Amount of £2,509.51 applies to HMRC gov bonus. Breach raised with engineering and product 09/10. - Engineering corrected £341.50 on 23/03 and debited from the overall amount of 2,509.51 on 24/03 bringing the total difference to £2,168.01.
...

Sheet Unalloc_Data
A1: Copy data from "CISA Unalloc Ledger and Payins" with previous day's date | P1: CISA | AD1: CISA | AU1: CISA | BI1: LISA
P2: Brings previous day's data from Unalloc_Rec tab | AD2: Brings previous day's data from Unalloc_Rec sheet for comparison with the new data | AU2: Brings the final data sorted that need to be put on the Unalloc Rec tab | BI2: Brings the final data sorted that need to be put on the Unalloc Rec tab
A3: user_id | B3: ledger_entry_id | C3: ledger_entry_created_at | D3: ledger_entry_type | E3: ledger_entry_amount | F3: product | G3: subscription_id | H3: collection_id | I3: transaction_id | J3: provider_id | K3: payin_amount | L3: transaction_type | M3: payin_created_at | AD3: =IFERROR(__xludf.DUMMYFUNCTION("{FILTER('3. Unalloc Rec'!C3:O983, '3. Unalloc Rec'!H3:H983 = ""cash_isa""); QUERY(A3:M1000, ""select * where F = 'cash_isa'"", 0)}"),"73df5aae-f42a-49a0-9d8f-616ca6dbebaa") -> 73df5aae-f42a-49a0-9d8f-616ca6dbebaa | AE3: =IFERROR(__xludf.DUMMYFUNCTION("""COMPUTED_VALUE"""),"019eb1df-f256-71a1-b1ce-7c7ae8b244bc") -> 019eb1df-f256-71a1-b1ce-7c7ae8b244bc | AF3: =IFERROR(__xludf.DUMMYFUNCTION("""COMPUTED_VALUE"""),46183.59097222222) -> 46183.591 | AG3: =IFERROR(__xludf.DUMMYFUNCTION("""COMPUTED_VALUE"""),"credit") -> credit | AH3: =IFERROR(__xludf.DUMMYFUNCTION("""COMPUTED_VALUE"""),"29997.68") -> 29997.68 | AI3: =IFERROR(__xludf.DUMMYFUNCTION("""COMPUTED_VALUE"""),"cash_isa") -> cash_isa | AJ3: =IFERROR(__xludf.DUMMYFUNCTION("""COMPUTED_VALUE"""),"9bc00e6b-ce5f-48c5-ae3a-1baabe00f337") -> 9bc00e6b-ce5f-48c5-ae3a-1baabe00f337 | AK3: =IFERROR(__xludf.DUMMYFUNCTION("""COMPUTED_VALUE"""),"e3a86178-e782-4b8e-a5af-c71a91f91e51") -> e3a86178-e782-4b8e-a5af-c71a91f91e51 | AL3: =IFERROR(__xludf.DUMMYFUNCTION("""COMPUTED_VALUE"""),"e3a86178-e782-4b8e-a5af-c71a91f91e51") -> e3a86178-e782-4b8e-a5af-c71a91f91e51 | AM3: =IFERROR(__xludf.DUMMYFUNCTION("""COMPUTED_VALUE"""),"400250 51421336-2136136478") -> 400250 51421336-2136136478 | AN3: =IFERROR(__xludf.DUMMYFUNCTION("""COMPUTED_VALUE"""),29997.68) -> 29997.68 | AO3: =IFERROR(__xludf.DUMMYFUNCTION("""COMPUTED_VALUE"""),"payin") -> payin | AP3: =IFERROR(__xludf.DUMMYFUNCTION("""COMPUTED_VALUE"""),46182.22638888889) -> 46182.226 | AR3: =ROUND(VALUE(AH3),2)&"_"&TRIM(LOWER(AG3)) -> 29997.68_credit | AS3: =IF(AH3="", "", LET(current_amt, ROUND(VALUE(AH3), 2), current_dir, TRIM(LOWER(AG3)), opposite_dir, IF(current_dir="credit", "debit", "credit"), occ, COUNTIFS($AH$3:AH3, AH3, $AG$3:AG3, AG3), opp_total, COUNTIFS($AH$3:$AH$1000, AH3, $AG$3:$AG$1000, opposite_dir), IF(opp_total >= occ, "DROP", "KEEP"))) -> KEEP | AU3: =IFERROR(__xludf.DUMMYFUNCTION("SORT(FILTER(AD3:AP1000, AS3:AS1000=""KEEP""),3,TRUE)"),"73df5aae-f42a-49a0-9d8f-616ca6dbebaa") -> 73df5aae-f42a-49a0-9d8f-616ca6dbebaa | AV3: =IFERROR(__xludf.DUMMYFUNCTION("""COMPUTED_VALUE"""),"019eb1df-f256-71a1-b1ce-7c7ae8b244bc") -> 019eb1df-f256-71a1-b1ce-7c7ae8b244bc | AW3: =IFERROR(__xludf.DUMMYFUNCTION("""COMPUTED_VALUE"""),46183.59097222222) -> 46183.591 | AX3: =IFERROR(__xludf.DUMMYFUNCTION("""COMPUTED_VALUE"""),"credit") -> credit | AY3: =IFERROR(__xludf.DUMMYFUNCTION("""COMPUTED_VALUE"""),"29997.68") -> 29997.68 | AZ3: =IFERROR(__xludf.DUMMYFUNCTION("""COMPUTED_VALUE"""),"cash_isa") -> cash_isa | BA3: =IFERROR(__xludf.DUMMYFUNCTION("""COMPUTED_VALUE"""),"9bc00e6b-ce5f-48c5-ae3a-1baabe00f337") -> 9bc00e6b-ce5f-48c5-ae3a-1baabe00f337 | BB3: =IFERROR(__xludf.DUMMYFUNCTION("""COMPUTED_VALUE"""),"e3a86178-e782-4b8e-a5af-c71a91f91e51") -> e3a86178-e782-4b8e-a5af-c71a91f91e51 | BC3: =IFERROR(__xludf.DUMMYFUNCTION("""COMPUTED_VALUE"""),"e3a86178-e782-4b8e-a5af-c71a91f91e51") -> e3a86178-e782-4b8e-a5af-c71a91f91e51 | BD3: =IFERROR(__xludf.DUMMYFUNCTION("""COMPUTED_VALUE"""),"400250 51421336-2136136478") -> 400250 51421336-2136136478 | BE3: =IFERROR(__xludf.DUMMYFUNCTION("""COMPUTED_VALUE"""),29997.68) -> 29997.68 | BF3: =IFERROR(__xludf.DUMMYFUNCTION("""COMPUTED_VALUE"""),"payin") -> payin | BG3: =IFERROR(__xludf.DUMMYFUNCTION("""COMPUTED_VALUE"""),46182.22638888889) -> 46182.226 | BI3: =IFERROR(__xludf.DUMMYFUNCTION("SORT(FILTER(AD1557:AP5000, AS1557:AS5000=""KEEP""),3,TRUE)"),"73df5aae-f42a-49a0-9d8f-616ca6dbebaa") -> 73df5aae-f42a-49a0-9d8f-616ca6dbebaa | BJ3: =IFERROR(__xludf.DUMMYFUNCTION("""COMPUTED_VALUE"""),"0199816b-0e35-745a-bffb-2eb385b18f78") -> 0199816b-0e35-745a-bffb-2eb385b18f78 | BK3: =IFERROR(__xludf.DUMMYFUNCTION("""COMPUTED_VALUE"""),45925.63055555556) -> 45925.631 | BL3: =IFERROR(__xludf.DUMMYFUNCTION("""COMPUTED_VALUE"""),"credit") -> credit | BM3: =IFERROR(__xludf.DUMMYFUNCTION("""COMPUTED_VALUE"""),"25.82") -> 25.82 | BN3: =IFERROR(__xludf.DUMMYFUNCTION("""COMPUTED_VALUE"""),"lisa") -> lisa | BO3: =IFERROR(__xludf.DUMMYFUNCTION("""COMPUTED_VALUE"""),"b7a59586-5d10-4989-91c2-f2376c7a6ab2") -> b7a59586-5d10-4989-91c2-f2376c7a6ab2 | BP3: =IFERROR(__xludf.DUMMYFUNCTION("""COMPUTED_VALUE"""),"8ecd675b-d3b5-4b51-9aee-fc2c558679b5") -> 8ecd675b-d3b5-4b51-9aee-fc2c558679b5 | BS3: =IFERROR(__xludf.DUMMYFUNCTION("""COMPUTED_VALUE"""),25.82) -> 25.82
A4: 73df5aae-f42a-49a0-9d8f-616ca6dbebaa | B4: 019ecf66-4e5f-7d1d-ab8b-3f663490584d | C4: 46189.325 | D4: credit | E4: 6879.1 | F4: cash_isa | G4: 9bc00e6b-ce5f-48c5-ae3a-1baabe00f337 | H4: 91d3f2bc-40eb-40b5-abfd-b8c37565b61e | AD4: =IFERROR(__xludf.DUMMYFUNCTION("""COMPUTED_VALUE"""),"73df5aae-f42a-49a0-9d8f-616ca6dbebaa") -> 73df5aae-f42a-49a0-9d8f-616ca6dbebaa | AE4: =IFERROR(__xludf.DUMMYFUNCTION("""COMPUTED_VALUE"""),"019eb6b9-c0a2-7317-ab4a-c235d039858e") -> 019eb6b9-c0a2-7317-ab4a-c235d039858e | AF4: =IFERROR(__xludf.DUMMYFUNCTION("""COMPUTED_VALUE"""),46184.53333333333) -> 46184.533 | AG4: =IFERROR(__xludf.DUMMYFUNCTION("""COMPUTED_VALUE"""),"credit") -> credit | AH4: =IFERROR(__xludf.DUMMYFUNCTION("""COMPUTED_VALUE"""),18184.43) -> 18184.43 | AI4: =IFERROR(__xludf.DUMMYFUNCTION("""COMPUTED_VALUE"""),"cash_isa") -> cash_isa | AJ4: =IFERROR(__xludf.DUMMYFUNCTION("""COMPUTED_VALUE"""),"9bc00e6b-ce5f-48c5-ae3a-1baabe00f337") -> 9bc00e6b-ce5f-48c5-ae3a-1baabe00f337 | AK4: =IFERROR(__xludf.DUMMYFUNCTION("""COMPUTED_VALUE"""),"8a36818d-cb4b-4b51-98cd-feffaecfad30") -> 8a36818d-cb4b-4b51-98cd-feffaecfad30 | AL4: =IFERROR(__xludf.DUMMYFUNCTION("""COMPUTED_VALUE"""),"8a36818d-cb4b-4b51-98cd-feffaecfad30") -> 8a36818d-cb4b-4b51-98cd-feffaecfad30 | AM4: =IFERROR(__xludf.DUMMYFUNCTION("""COMPUTED_VALUE"""),"13267202-51989231") -> 13267202-51989231 | AN4: =IFERROR(__xludf.DUMMYFUNCTION("""COMPUTED_VALUE"""),18184.43) -> 18184.43 | AO4: =IFERROR(__xludf.DUMMYFUNCTION("""COMPUTED_VALUE"""),"payin") -> payin | AP4: =IFERROR(__xludf.DUMMYFUNCTION("""COMPUTED_VALUE"""),46183.16875) -> 46183.169 | AR4: =ROUND(VALUE(AH4),2)&"_"&TRIM(LOWER(AG4)) -> 18184.43_credit | AS4: =IF(AH4="", "", LET(current_amt, ROUND(VALUE(AH4), 2), current_dir, TRIM(LOWER(AG4)), opposite_dir, IF(current_dir="credit", "debit", "credit"), occ, COUNTIFS($AH$3:AH4, AH4, $AG$3:AG4, AG4), opp_total, COUNTIFS($AH$3:$AH$1000, AH4, $AG$3:$AG$1000, opposite_dir), IF(opp_total >= occ, "DROP", "KEEP"))) -> KEEP | AU4: =IFERROR(__xludf.DUMMYFUNCTION("""COMPUTED_VALUE"""),"73df5aae-f42a-49a0-9d8f-616ca6dbebaa") -> 73df5aae-f42a-49a0-9d8f-616ca6dbebaa | AV4: =IFERROR(__xludf.DUMMYFUNCTION("""COMPUTED_VALUE"""),"019eb6b9-c0a2-7317-ab4a-c235d039858e") -> 019eb6b9-c0a2-7317-ab4a-c235d039858e | AW4: =IFERROR(__xludf.DUMMYFUNCTION("""COMPUTED_VALUE"""),46184.53333333333) -> 46184.533 | AX4: =IFERROR(__xludf.DUMMYFUNCTION("""COMPUTED_VALUE"""),"credit") -> credit | AY4: =IFERROR(__xludf.DUMMYFUNCTION("""COMPUTED_VALUE"""),18184.43) -> 18184.43 | AZ4: =IFERROR(__xludf.DUMMYFUNCTION("""COMPUTED_VALUE"""),"cash_isa") -> cash_isa | BA4: =IFERROR(__xludf.DUMMYFUNCTION("""COMPUTED_VALUE"""),"9bc00e6b-ce5f-48c5-ae3a-1baabe00f337") -> 9bc00e6b-ce5f-48c5-ae3a-1baabe00f337 | BB4: =IFERROR(__xludf.DUMMYFUNCTION("""COMPUTED_VALUE"""),"8a36818d-cb4b-4b51-98cd-feffaecfad30") -> 8a36818d-cb4b-4b51-98cd-feffaecfad30 | BC4: =IFERROR(__xludf.DUMMYFUNCTION("""COMPUTED_VALUE"""),"8a36818d-cb4b-4b51-98cd-feffaecfad30") -> 8a36818d-cb4b-4b51-98cd-feffaecfad30 | BD4: =IFERROR(__xludf.DUMMYFUNCTION("""COMPUTED_VALUE"""),"13267202-51989231") -> 13267202-51989231 | BE4: =IFERROR(__xludf.DUMMYFUNCTION("""COMPUTED_VALUE"""),18184.43) -> 18184.43 | BF4: =IFERROR(__xludf.DUMMYFUNCTION("""COMPUTED_VALUE"""),"payin") -> payin | BG4: =IFERROR(__xludf.DUMMYFUNCTION("""COMPUTED_VALUE"""),46183.16875) -> 46183.169 | BI4: =IFERROR(__xludf.DUMMYFUNCTION("""COMPUTED_VALUE"""),"73df5aae-f42a-49a0-9d8f-616ca6dbebaa") -> 73df5aae-f42a-49a0-9d8f-616ca6dbebaa | BJ4: =IFERROR(__xludf.DUMMYFUNCTION("""COMPUTED_VALUE"""),"019a265f-0027-7d29-8ff1-8f39f64358c1") -> 019a265f-0027-7d29-8ff1-8f39f64358c1 | BK4: =IFERROR(__xludf.DUMMYFUNCTION("""COMPUTED_VALUE"""),45957.66111111111) -> 45957.661 | BL4: =IFERROR(__xludf.DUMMYFUNCTION("""COMPUTED_VALUE"""),"credit") -> credit | BM4: =IFERROR(__xludf.DUMMYFUNCTION("""COMPUTED_VALUE"""),"39.36") -> 39.36 | BN4: =IFERROR(__xludf.DUMMYFUNCTION("""COMPUTED_VALUE"""),"lisa") -> lisa | BO4: =IFERROR(__xludf.DUMMYFUNCTION("""COMPUTED_VALUE"""),"b7a59586-5d10-4989-91c2-f2376c7a6ab2") -> b7a59586-5d10-4989-91c2-f2376c7a6ab2 | BP4: =IFERROR(__xludf.DUMMYFUNCTION("""COMPUTED_VALUE"""),"7464d141-4aaa-46a8-ae96-c3c7997dfc03") -> 7464d141-4aaa-46a8-ae96-c3c7997dfc03 | BS4: =IFERROR(__xludf.DUMMYFUNCTION("""COMPUTED_VALUE"""),39.36) -> 39.36
A5: 73df5aae-f42a-49a0-9d8f-616ca6dbebaa | B5: 019ecf67-f3f8-7864-b2db-1d9be3c1983e | C5: 46189.326 | D5: debit | E5: 6879.1 | F5: cash_isa | G5: 9bc00e6b-ce5f-48c5-ae3a-1baabe00f337 | H5: 91d3f2bc-40eb-40b5-abfd-b8c37565b61e | AD5: =IFERROR(__xludf.DUMMYFUNCTION("""COMPUTED_VALUE"""),"73df5aae-f42a-49a0-9d8f-616ca6dbebaa") -> 73df5aae-f42a-49a0-9d8f-616ca6dbebaa | AE5: =IFERROR(__xludf.DUMMYFUNCTION("""COMPUTED_VALUE"""),"019ecb64-c843-7d12-81ee-f6401245704f") -> 019ecb64-c843-7d12-81ee-f6401245704f | AF5: =IFERROR(__xludf.DUMMYFUNCTION("""COMPUTED_VALUE"""),46188.54675925926) -> 46188.547 | AG5: =IFERROR(__xludf.DUMMYFUNCTION("""COMPUTED_VALUE"""),"credit") -> credit | AH5: =IFERROR(__xludf.DUMMYFUNCTION("""COMPUTED_VALUE"""),64323.37) -> 64323.37 | AI5: =IFERROR(__xludf.DUMMYFUNCTION("""COMPUTED_VALUE"""),"cash_isa") -> cash_isa | AJ5: =IFERROR(__xludf.DUMMYFUNCTION("""COMPUTED_VALUE"""),"9bc00e6b-ce5f-48c5-ae3a-1baabe00f337") -> 9bc00e6b-ce5f-48c5-ae3a-1baabe00f337 | AK5: =IFERROR(__xludf.DUMMYFUNCTION("""COMPUTED_VALUE"""),"79376e9a-a2d9-4da6-80da-2fccb69993e9") -> 79376e9a-a2d9-4da6-80da-2fccb69993e9 | AL5: =IFERROR(__xludf.DUMMYFUNCTION("""COMPUTED_VALUE"""),"79376e9a-a2d9-4da6-80da-2fccb69993e9") -> 79376e9a-a2d9-4da6-80da-2fccb69993e9 | AM5: =IFERROR(__xludf.DUMMYFUNCTION("""COMPUTED_VALUE"""),"NOREF-878813225") -> NOREF-878813225 | AN5: =IFERROR(__xludf.DUMMYFUNCTION("""COMPUTED_VALUE"""),64323.37) -> 64323.37 | AO5: =IFERROR(__xludf.DUMMYFUNCTION("""COMPUTED_VALUE"""),"payin") -> payin | AP5: =IFERROR(__xludf.DUMMYFUNCTION("""COMPUTED_VALUE"""),46185.08598379629) -> 46185.086 | AR5: =ROUND(VALUE(AH5),2)&"_"&TRIM(LOWER(AG5)) -> 64323.37_credit | AS5: =IF(AH5="", "", LET(current_amt, ROUND(VALUE(AH5), 2), current_dir, TRIM(LOWER(AG5)), opposite_dir, IF(current_dir="credit", "debit", "credit"), occ, COUNTIFS($AH$3:AH5, AH5, $AG$3:AG5, AG5), opp_total, COUNTIFS($AH$3:$AH$1000, AH5, $AG$3:$AG$1000, opposite_dir), IF(opp_total >= occ, "DROP", "KEEP"))) -> KEEP | AU5: =IFERROR(__xludf.DUMMYFUNCTION("""COMPUTED_VALUE"""),"73df5aae-f42a-49a0-9d8f-616ca6dbebaa") -> 73df5aae-f42a-49a0-9d8f-616ca6dbebaa | AV5: =IFERROR(__xludf.DUMMYFUNCTION("""COMPUTED_VALUE"""),"019ecb64-c843-7d12-81ee-f6401245704f") -> 019ecb64-c843-7d12-81ee-f6401245704f | AW5: =IFERROR(__xludf.DUMMYFUNCTION("""COMPUTED_VALUE"""),46188.54675925926) -> 46188.547 | AX5: =IFERROR(__xludf.DUMMYFUNCTION("""COMPUTED_VALUE"""),"credit") -> credit | AY5: =IFERROR(__xludf.DUMMYFUNCTION("""COMPUTED_VALUE"""),64323.37) -> 64323.37 | AZ5: =IFERROR(__xludf.DUMMYFUNCTION("""COMPUTED_VALUE"""),"cash_isa") -> cash_isa | BA5: =IFERROR(__xludf.DUMMYFUNCTION("""COMPUTED_VALUE"""),"9bc00e6b-ce5f-48c5-ae3a-1baabe00f337") -> 9bc00e6b-ce5f-48c5-ae3a-1baabe00f337 | BB5: =IFERROR(__xludf.DUMMYFUNCTION("""COMPUTED_VALUE"""),"79376e9a-a2d9-4da6-80da-2fccb69993e9") -> 79376e9a-a2d9-4da6-80da-2fccb69993e9 | BC5: =IFERROR(__xludf.DUMMYFUNCTION("""COMPUTED_VALUE"""),"79376e9a-a2d9-4da6-80da-2fccb69993e9") -> 79376e9a-a2d9-4da6-80da-2fccb69993e9 | BD5: =IFERROR(__xludf.DUMMYFUNCTION("""COMPUTED_VALUE"""),"NOREF-878813225") -> NOREF-878813225 | BE5: =IFERROR(__xludf.DUMMYFUNCTION("""COMPUTED_VALUE"""),64323.37) -> 64323.37 | BF5: =IFERROR(__xludf.DUMMYFUNCTION("""COMPUTED_VALUE"""),"payin") -> payin | BG5: =IFERROR(__xludf.DUMMYFUNCTION("""COMPUTED_VALUE"""),46185.08598379629) -> 46185.086 | BI5: =IFERROR(__xludf.DUMMYFUNCTION("""COMPUTED_VALUE"""),"73df5aae-f42a-49a0-9d8f-616ca6dbebaa") -> 73df5aae-f42a-49a0-9d8f-616ca6dbebaa | BJ5: =IFERROR(__xludf.DUMMYFUNCTION("""COMPUTED_VALUE"""),"019c0522-3a07-719b-bcbd-b2f0eb14e013") -> 019c0522-3a07-719b-bcbd-b2f0eb14e013 | BK5: =IFERROR(__xludf.DUMMYFUNCTION("""COMPUTED_VALUE"""),46050.62777777778) -> 46050.628 | BL5: =IFERROR(__xludf.DUMMYFUNCTION("""COMPUTED_VALUE"""),"credit") -> credit | BM5: =IFERROR(__xludf.DUMMYFUNCTION("""COMPUTED_VALUE"""),"1250.5") -> 1250.5 | BN5: =IFERROR(__xludf.DUMMYFUNCTION("""COMPUTED_VALUE"""),"lisa") -> lisa | BO5: =IFERROR(__xludf.DUMMYFUNCTION("""COMPUTED_VALUE"""),"b7a59586-5d10-4989-91c2-f2376c7a6ab2") -> b7a59586-5d10-4989-91c2-f2376c7a6ab2 | BP5: =IFERROR(__xludf.DUMMYFUNCTION("""COMPUTED_VALUE"""),"7464d141-4aaa-46a8-ae96-c3c7997dfc03") -> 7464d141-4aaa-46a8-ae96-c3c7997dfc03 | BS5: =IFERROR(__xludf.DUMMYFUNCTION("""COMPUTED_VALUE"""),1250.5) -> 1250.5
A6: 73df5aae-f42a-49a0-9d8f-616ca6dbebaa | B6: 019ecf6b-b130-7c98-ab0b-5639f735de4f | C6: 46189.329 | D6: credit | E6: 1000 | F6: cash_isa | G6: 9bc00e6b-ce5f-48c5-ae3a-1baabe00f337 | H6: 594e43b2-4c16-4cdd-9a32-89078ce028d1 | AD6: =IFERROR(__xludf.DUMMYFUNCTION("""COMPUTED_VALUE"""),"73df5aae-f42a-49a0-9d8f-616ca6dbebaa") -> 73df5aae-f42a-49a0-9d8f-616ca6dbebaa | AE6: =IFERROR(__xludf.DUMMYFUNCTION("""COMPUTED_VALUE"""),"019ecb64-c733-7ae4-944c-db2cb0274f72") -> 019ecb64-c733-7ae4-944c-db2cb0274f72 | AF6: =IFERROR(__xludf.DUMMYFUNCTION("""COMPUTED_VALUE"""),46188.54675925926) -> 46188.547 | AG6: =IFERROR(__xludf.DUMMYFUNCTION("""COMPUTED_VALUE"""),"credit") -> credit | AH6: =IFERROR(__xludf.DUMMYFUNCTION("""COMPUTED_VALUE"""),40492.94) -> 40492.94 | AI6: =IFERROR(__xludf.DUMMYFUNCTION("""COMPUTED_VALUE"""),"cash_isa") -> cash_isa | AJ6: =IFERROR(__xludf.DUMMYFUNCTION("""COMPUTED_VALUE"""),"9bc00e6b-ce5f-48c5-ae3a-1baabe00f337") -> 9bc00e6b-ce5f-48c5-ae3a-1baabe00f337 | AK6: =IFERROR(__xludf.DUMMYFUNCTION("""COMPUTED_VALUE"""),"d1610b83-cb8b-45f0-bea4-69fec40f5e82") -> d1610b83-cb8b-45f0-bea4-69fec40f5e82 | AL6: =IFERROR(__xludf.DUMMYFUNCTION("""COMPUTED_VALUE"""),"d1610b83-cb8b-45f0-bea4-69fec40f5e82") -> d1610b83-cb8b-45f0-bea4-69fec40f5e82 | AM6: =IFERROR(__xludf.DUMMYFUNCTION("""COMPUTED_VALUE"""),"NOREF-1362020235") -> NOREF-1362020235 | AN6: =IFERROR(__xludf.DUMMYFUNCTION("""COMPUTED_VALUE"""),40492.94) -> 40492.94 | AO6: =IFERROR(__xludf.DUMMYFUNCTION("""COMPUTED_VALUE"""),"payin") -> payin | AP6: =IFERROR(__xludf.DUMMYFUNCTION("""COMPUTED_VALUE"""),46185.668761574074) -> 46185.669 | AR6: =ROUND(VALUE(AH6),2)&"_"&TRIM(LOWER(AG6)) -> 40492.94_credit | AS6: =IF(AH6="", "", LET(current_amt, ROUND(VALUE(AH6), 2), current_dir, TRIM(LOWER(AG6)), opposite_dir, IF(current_dir="credit", "debit", "credit"), occ, COUNTIFS($AH$3:AH6, AH6, $AG$3:AG6, AG6), opp_total, COUNTIFS($AH$3:$AH$1000, AH6, $AG$3:$AG$1000, opposite_dir), IF(opp_total >= occ, "DROP", "KEEP"))) -> KEEP | AU6: =IFERROR(__xludf.DUMMYFUNCTION("""COMPUTED_VALUE"""),"73df5aae-f42a-49a0-9d8f-616ca6dbebaa") -> 73df5aae-f42a-49a0-9d8f-616ca6dbebaa | AV6: =IFERROR(__xludf.DUMMYFUNCTION("""COMPUTED_VALUE"""),"019ecb64-c733-7ae4-944c-db2cb0274f72") -> 019ecb64-c733-7ae4-944c-db2cb0274f72 | AW6: =IFERROR(__xludf.DUMMYFUNCTION("""COMPUTED_VALUE"""),46188.54675925926) -> 46188.547 | AX6: =IFERROR(__xludf.DUMMYFUNCTION("""COMPUTED_VALUE"""),"credit") -> credit | AY6: =IFERROR(__xludf.DUMMYFUNCTION("""COMPUTED_VALUE"""),40492.94) -> 40492.94 | AZ6: =IFERROR(__xludf.DUMMYFUNCTION("""COMPUTED_VALUE"""),"cash_isa") -> cash_isa | BA6: =IFERROR(__xludf.DUMMYFUNCTION("""COMPUTED_VALUE"""),"9bc00e6b-ce5f-48c5-ae3a-1baabe00f337") -> 9bc00e6b-ce5f-48c5-ae3a-1baabe00f337 | BB6: =IFERROR(__xludf.DUMMYFUNCTION("""COMPUTED_VALUE"""),"d1610b83-cb8b-45f0-bea4-69fec40f5e82") -> d1610b83-cb8b-45f0-bea4-69fec40f5e82 | BC6: =IFERROR(__xludf.DUMMYFUNCTION("""COMPUTED_VALUE"""),"d1610b83-cb8b-45f0-bea4-69fec40f5e82") -> d1610b83-cb8b-45f0-bea4-69fec40f5e82 | BD6: =IFERROR(__xludf.DUMMYFUNCTION("""COMPUTED_VALUE"""),"NOREF-1362020235") -> NOREF-1362020235 | BE6: =IFERROR(__xludf.DUMMYFUNCTION("""COMPUTED_VALUE"""),40492.94) -> 40492.94 | BF6: =IFERROR(__xludf.DUMMYFUNCTION("""COMPUTED_VALUE"""),"payin") -> payin | BG6: =IFERROR(__xludf.DUMMYFUNCTION("""COMPUTED_VALUE"""),46185.668761574074) -> 46185.669 | BI6: =IFERROR(__xludf.DUMMYFUNCTION("""COMPUTED_VALUE"""),"73df5aae-f42a-49a0-9d8f-616ca6dbebaa") -> 73df5aae-f42a-49a0-9d8f-616ca6dbebaa | BJ6: =IFERROR(__xludf.DUMMYFUNCTION("""COMPUTED_VALUE"""),"019c9e6e-9ac8-7b3e-a27b-af919f6932b8") -> 019c9e6e-9ac8-7b3e-a27b-af919f6932b8 | BK6: =IFERROR(__xludf.DUMMYFUNCTION("""COMPUTED_VALUE"""),46080.39513888889) -> 46080.395 | BL6: =IFERROR(__xludf.DUMMYFUNCTION("""COMPUTED_VALUE"""),"credit") -> credit | BM6: =IFERROR(__xludf.DUMMYFUNCTION("""COMPUTED_VALUE"""),"2509.51") -> 2509.51 | BN6: =IFERROR(__xludf.DUMMYFUNCTION("""COMPUTED_VALUE"""),"lisa") -> lisa | BO6: =IFERROR(__xludf.DUMMYFUNCTION("""COMPUTED_VALUE"""),"b7a59586-5d10-4989-91c2-f2376c7a6ab2") -> b7a59586-5d10-4989-91c2-f2376c7a6ab2 | BP6: =IFERROR(__xludf.DUMMYFUNCTION("""COMPUTED_VALUE"""),"7464d141-4aaa-46a8-ae96-c3c7997dfc03") -> 7464d141-4aaa-46a8-ae96-c3c7997dfc03 | BS6: =IFERROR(__xludf.DUMMYFUNCTION("""COMPUTED_VALUE"""),2168.01) -> 2168.01
A7: 73df5aae-f42a-49a0-9d8f-616ca6dbebaa | B7: 019ecf6d-7783-75cc-a067-1d4535a564d3 | C7: 46189.33 | D7: debit | E7: 1000 | F7: cash_isa | G7: 9bc00e6b-ce5f-48c5-ae3a-1baabe00f337 | H7: 594e43b2-4c16-4cdd-9a32-89078ce028d1 | AD7: =IFERROR(__xludf.DUMMYFUNCTION("""COMPUTED_VALUE"""),"73df5aae-f42a-49a0-9d8f-616ca6dbebaa") -> 73df5aae-f42a-49a0-9d8f-616ca6dbebaa | AE7: =IFERROR(__xludf.DUMMYFUNCTION("""COMPUTED_VALUE"""),"019ed024-854b-7377-878e-9bd25cd97072") -> 019ed024-854b-7377-878e-9bd25cd97072 | AF7: =IFERROR(__xludf.DUMMYFUNCTION("""COMPUTED_VALUE"""),46189.468923611115) -> 46189.469 | AG7: =IFERROR(__xludf.DUMMYFUNCTION("""COMPUTED_VALUE"""),"credit") -> credit | AH7: =IFERROR(__xludf.DUMMYFUNCTION("""COMPUTED_VALUE"""),21471.6) -> 21471.6 | AI7: =IFERROR(__xludf.DUMMYFUNCTION("""COMPUTED_VALUE"""),"cash_isa") -> cash_isa | AJ7: =IFERROR(__xludf.DUMMYFUNCTION("""COMPUTED_VALUE"""),"9bc00e6b-ce5f-48c5-ae3a-1baabe00f337") -> 9bc00e6b-ce5f-48c5-ae3a-1baabe00f337 | AK7: =IFERROR(__xludf.DUMMYFUNCTION("""COMPUTED_VALUE"""),"228cd2f5-1ee0-4962-a649-82c9f17961ae") -> 228cd2f5-1ee0-4962-a649-82c9f17961ae | AL7: =IFERROR(__xludf.DUMMYFUNCTION("""COMPUTED_VALUE"""),"228cd2f5-1ee0-4962-a649-82c9f17961ae") -> 228cd2f5-1ee0-4962-a649-82c9f17961ae | AM7: =IFERROR(__xludf.DUMMYFUNCTION("""COMPUTED_VALUE"""),"WK648730Ba-580073357") -> WK648730Ba-580073357 | AN7: =IFERROR(__xludf.DUMMYFUNCTION("""COMPUTED_VALUE"""),21471.6) -> 21471.6 | AO7: =IFERROR(__xludf.DUMMYFUNCTION("""COMPUTED_VALUE"""),"payin") -> payin | AP7: =IFERROR(__xludf.DUMMYFUNCTION("""COMPUTED_VALUE"""),46188.66883101852) -> 46188.669 | AR7: =ROUND(VALUE(AH7),2)&"_"&TRIM(LOWER(AG7)) -> 21471.6_credit | AS7: =IF(AH7="", "", LET(current_amt, ROUND(VALUE(AH7), 2), current_dir, TRIM(LOWER(AG7)), opposite_dir, IF(current_dir="credit", "debit", "credit"), occ, COUNTIFS($AH$3:AH7, AH7, $AG$3:AG7, AG7), opp_total, COUNTIFS($AH$3:$AH$1000, AH7, $AG$3:$AG$1000, opposite_dir), IF(opp_total >= occ, "DROP", "KEEP"))) -> KEEP | AU7: =IFERROR(__xludf.DUMMYFUNCTION("""COMPUTED_VALUE"""),"73df5aae-f42a-49a0-9d8f-616ca6dbebaa") -> 73df5aae-f42a-49a0-9d8f-616ca6dbebaa | AV7: =IFERROR(__xludf.DUMMYFUNCTION("""COMPUTED_VALUE"""),"019ecfae-a956-7cee-9cd6-cc020e483641") -> 019ecfae-a956-7cee-9cd6-cc020e483641 | AW7: =IFERROR(__xludf.DUMMYFUNCTION("""COMPUTED_VALUE"""),46189.379525462966) -> 46189.38 | AX7: =IFERROR(__xludf.DUMMYFUNCTION("""COMPUTED_VALUE"""),"debit") -> debit | AY7: =IFERROR(__xludf.DUMMYFUNCTION("""COMPUTED_VALUE"""),13326.74) -> 13326.74 | AZ7: =IFERROR(__xludf.DUMMYFUNCTION("""COMPUTED_VALUE"""),"cash_isa") -> cash_isa | BA7: =IFERROR(__xludf.DUMMYFUNCTION("""COMPUTED_VALUE"""),"9bc00e6b-ce5f-48c5-ae3a-1baabe00f337") -> 9bc00e6b-ce5f-48c5-ae3a-1baabe00f337 | BB7: =IFERROR(__xludf.DUMMYFUNCTION("""COMPUTED_VALUE"""),"f0a37a7e-0033-47e7-97ae-2a9b66aa8fa6") -> f0a37a7e-0033-47e7-97ae-2a9b66aa8fa6 | BC7: =IFERROR(__xludf.DUMMYFUNCTION("""COMPUTED_VALUE"""),"f0a37a7e-0033-47e7-97ae-2a9b66aa8fa6") -> f0a37a7e-0033-47e7-97ae-2a9b66aa8fa6 | BE7: =IFERROR(__xludf.DUMMYFUNCTION("""COMPUTED_VALUE"""),13326.74) -> 13326.74 | BF7: =IFERROR(__xludf.DUMMYFUNCTION("""COMPUTED_VALUE"""),"payout") -> payout | BG7: =IFERROR(__xludf.DUMMYFUNCTION("""COMPUTED_VALUE"""),46183.25782407407) -> 46183.258 | BI7: =IFERROR(__xludf.DUMMYFUNCTION("""COMPUTED_VALUE"""),"73df5aae-f42a-49a0-9d8f-616ca6dbebaa") -> 73df5aae-f42a-49a0-9d8f-616ca6dbebaa | BJ7: =IFERROR(__xludf.DUMMYFUNCTION("""COMPUTED_VALUE"""),"019e986b-6909-779a-852a-fdf77fb1f880") -> 019e986b-6909-779a-852a-fdf77fb1f880 | BK7: =IFERROR(__xludf.DUMMYFUNCTION("""COMPUTED_VALUE"""),46178.64857638889) -> 46178.649 | BL7: =IFERROR(__xludf.DUMMYFUNCTION("""COMPUTED_VALUE"""),"credit") -> credit | BM7: =IFERROR(__xludf.DUMMYFUNCTION("""COMPUTED_VALUE"""),13.99) -> 13.99 | BN7: =IFERROR(__xludf.DUMMYFUNCTION("""COMPUTED_VALUE"""),"lisa") -> lisa | BO7: =IFERROR(__xludf.DUMMYFUNCTION("""COMPUTED_VALUE"""),"b7a59586-5d10-4989-91c2-f2376c7a6ab2") -> b7a59586-5d10-4989-91c2-f2376c7a6ab2 | BP7: =IFERROR(__xludf.DUMMYFUNCTION("""COMPUTED_VALUE"""),"6e288a26-6f54-4606-af76-43cc91f9103c") -> 6e288a26-6f54-4606-af76-43cc91f9103c | BQ7: =IFERROR(__xludf.DUMMYFUNCTION("""COMPUTED_VALUE"""),"6e288a26-6f54-4606-af76-43cc91f9103c") -> 6e288a26-6f54-4606-af76-43cc91f9103c | BR7: =IFERROR(__xludf.DUMMYFUNCTION("""COMPUTED_VALUE"""),"NOREF-190470356") -> NOREF-190470356 | BS7: =IFERROR(__xludf.DUMMYFUNCTION("""COMPUTED_VALUE"""),13.99) -> 13.99 | BT7: =IFERROR(__xludf.DUMMYFUNCTION("""COMPUTED_VALUE"""),"payin") -> payin | BU7: =IFERROR(__xludf.DUMMYFUNCTION("""COMPUTED_VALUE"""),46177.47902777778) -> 46177.479
A8: 73df5aae-f42a-49a0-9d8f-616ca6dbebaa | B8: 019ecf6e-8f11-753c-8898-9bf70a4b7f21 | C8: 46189.331 | D8: credit | E8: 21769.77 | F8: cash_isa | G8: 9bc00e6b-ce5f-48c5-ae3a-1baabe00f337 | H8: 9438e43a-27ed-4543-a6a9-a8d6dcc297fa | AD8: =IFERROR(__xludf.DUMMYFUNCTION("""COMPUTED_VALUE"""),"73df5aae-f42a-49a0-9d8f-616ca6dbebaa") -> 73df5aae-f42a-49a0-9d8f-616ca6dbebaa | AE8: =IFERROR(__xludf.DUMMYFUNCTION("""COMPUTED_VALUE"""),"019ed024-864c-78df-b53a-e34f6f766c49") -> 019ed024-864c-78df-b53a-e34f6f766c49 | AF8: =IFERROR(__xludf.DUMMYFUNCTION("""COMPUTED_VALUE"""),46189.468923611115) -> 46189.469 | AG8: =IFERROR(__xludf.DUMMYFUNCTION("""COMPUTED_VALUE"""),"credit") -> credit | AH8: =IFERROR(__xludf.DUMMYFUNCTION("""COMPUTED_VALUE"""),20974.52) -> 20974.52 | AI8: =IFERROR(__xludf.DUMMYFUNCTION("""COMPUTED_VALUE"""),"cash_isa") -> cash_isa | AJ8: =IFERROR(__xludf.DUMMYFUNCTION("""COMPUTED_VALUE"""),"9bc00e6b-ce5f-48c5-ae3a-1baabe00f337") -> 9bc00e6b-ce5f-48c5-ae3a-1baabe00f337 | AK8: =IFERROR(__xludf.DUMMYFUNCTION("""COMPUTED_VALUE"""),"084ad475-9333-4dbe-8fb5-7d7b8ad84064") -> 084ad475-9333-4dbe-8fb5-7d7b8ad84064 | AL8: =IFERROR(__xludf.DUMMYFUNCTION("""COMPUTED_VALUE"""),"084ad475-9333-4dbe-8fb5-7d7b8ad84064") -> 084ad475-9333-4dbe-8fb5-7d7b8ad84064 | AM8: =IFERROR(__xludf.DUMMYFUNCTION("""COMPUTED_VALUE"""),"NZ656284A-1098901635") -> NZ656284A-1098901635 | AN8: =IFERROR(__xludf.DUMMYFUNCTION("""COMPUTED_VALUE"""),20974.52) -> 20974.52 | AO8: =IFERROR(__xludf.DUMMYFUNCTION("""COMPUTED_VALUE"""),"payin") -> payin | AP8: =IFERROR(__xludf.DUMMYFUNCTION("""COMPUTED_VALUE"""),46188.66883101852) -> 46188.669 | AR8: =ROUND(VALUE(AH8),2)&"_"&TRIM(LOWER(AG8)) -> 20974.52_credit | AS8: =IF(AH8="", "", LET(current_amt, ROUND(VALUE(AH8), 2), current_dir, TRIM(LOWER(AG8)), opposite_dir, IF(current_dir="credit", "debit", "credit"), occ, COUNTIFS($AH$3:AH8, AH8, $AG$3:AG8, AG8), opp_total, COUNTIFS($AH$3:$AH$1000, AH8, $AG$3:$AG$1000, opposite_dir), IF(opp_total >= occ, "DROP", "KEEP"))) -> KEEP | AU8: =IFERROR(__xludf.DUMMYFUNCTION("""COMPUTED_VALUE"""),"73df5aae-f42a-49a0-9d8f-616ca6dbebaa") -> 73df5aae-f42a-49a0-9d8f-616ca6dbebaa | AV8: =IFERROR(__xludf.DUMMYFUNCTION("""COMPUTED_VALUE"""),"019ecfb2-4980-7229-903f-40db4994fdf1") -> 019ecfb2-4980-7229-903f-40db4994fdf1 | AW8: =IFERROR(__xludf.DUMMYFUNCTION("""COMPUTED_VALUE"""),46189.382268518515) -> 46189.382 | AX8: =IFERROR(__xludf.DUMMYFUNCTION("""COMPUTED_VALUE"""),"debit") -> debit | AY8: =IFERROR(__xludf.DUMMYFUNCTION("""COMPUTED_VALUE"""),18989.0) -> 18989 | AZ8: =IFERROR(__xludf.DUMMYFUNCTION("""COMPUTED_VALUE"""),"cash_isa") -> cash_isa | BA8: =IFERROR(__xludf.DUMMYFUNCTION("""COMPUTED_VALUE"""),"9bc00e6b-ce5f-48c5-ae3a-1baabe00f337") -> 9bc00e6b-ce5f-48c5-ae3a-1baabe00f337 | BB8: =IFERROR(__xludf.DUMMYFUNCTION("""COMPUTED_VALUE"""),"d02fd859-d682-4368-bc53-bdd594a15f1b") -> d02fd859-d682-4368-bc53-bdd594a15f1b | BC8: =IFERROR(__xludf.DUMMYFUNCTION("""COMPUTED_VALUE"""),"d02fd859-d682-4368-bc53-bdd594a15f1b") -> d02fd859-d682-4368-bc53-bdd594a15f1b | BD8: =IFERROR(__xludf.DUMMYFUNCTION("""COMPUTED_VALUE"""),"Return of Funds-501102174") -> Return of Funds-501102174 | BE8: =IFERROR(__xludf.DUMMYFUNCTION("""COMPUTED_VALUE"""),18989.0) -> 18989 | BF8: =IFERROR(__xludf.DUMMYFUNCTION("""COMPUTED_VALUE"""),"payin") -> payin | BG8: =IFERROR(__xludf.DUMMYFUNCTION("""COMPUTED_VALUE"""),46181.562314814815) -> 46181.562 | BI8: =IFERROR(__xludf.DUMMYFUNCTION("""COMPUTED_VALUE"""),"73df5aae-f42a-49a0-9d8f-616ca6dbebaa") -> 73df5aae-f42a-49a0-9d8f-616ca6dbebaa | BJ8: =IFERROR(__xludf.DUMMYFUNCTION("""COMPUTED_VALUE"""),"019ead2b-a847-7e9b-9cf2-ad8d1ba559ad") -> 019ead2b-a847-7e9b-9cf2-ad8d1ba559ad | BK8: =IFERROR(__xludf.DUMMYFUNCTION("""COMPUTED_VALUE"""),46182.67800925926) -> 46182.678 | BL8: =IFERROR(__xludf.DUMMYFUNCTION("""COMPUTED_VALUE"""),"credit") -> credit | BM8: =IFERROR(__xludf.DUMMYFUNCTION("""COMPUTED_VALUE"""),26032.55) -> 26032.55 | BN8: =IFERROR(__xludf.DUMMYFUNCTION("""COMPUTED_VALUE"""),"lisa") -> lisa | BO8: =IFERROR(__xludf.DUMMYFUNCTION("""COMPUTED_VALUE"""),"b7a59586-5d10-4989-91c2-f2376c7a6ab2") -> b7a59586-5d10-4989-91c2-f2376c7a6ab2 | BP8: =IFERROR(__xludf.DUMMYFUNCTION("""COMPUTED_VALUE"""),"ffe80a3e-ca2c-49f7-99e0-1fea99be39b5") -> ffe80a3e-ca2c-49f7-99e0-1fea99be39b5 | BQ8: =IFERROR(__xludf.DUMMYFUNCTION("""COMPUTED_VALUE"""),"ffe80a3e-ca2c-49f7-99e0-1fea99be39b5") -> ffe80a3e-ca2c-49f7-99e0-1fea99be39b5 | BR8: =IFERROR(__xludf.DUMMYFUNCTION("""COMPUTED_VALUE"""),"RETURN-810653200") -> RETURN-810653200 | BS8: =IFERROR(__xludf.DUMMYFUNCTION("""COMPUTED_VALUE"""),26032.55) -> 26032.55 | BT8: =IFERROR(__xludf.DUMMYFUNCTION("""COMPUTED_VALUE"""),"payin") -> payin | BU8: =IFERROR(__xludf.DUMMYFUNCTION("""COMPUTED_VALUE"""),46181.65377314815) -> 46181.654
A9: 73df5aae-f42a-49a0-9d8f-616ca6dbebaa | B9: 019ecf6f-d53d-72ab-945b-6e5f498392aa | C9: 46189.332 | D9: debit | E9: 21769.77 | F9: cash_isa | G9: 9bc00e6b-ce5f-48c5-ae3a-1baabe00f337 | H9: 9438e43a-27ed-4543-a6a9-a8d6dcc297fa | AD9: =IFERROR(__xludf.DUMMYFUNCTION("""COMPUTED_VALUE"""),"73df5aae-f42a-49a0-9d8f-616ca6dbebaa") -> 73df5aae-f42a-49a0-9d8f-616ca6dbebaa | AE9: =IFERROR(__xludf.DUMMYFUNCTION("""COMPUTED_VALUE"""),"019ed024-873d-7252-be6e-6e408eb5a4cb") -> 019ed024-873d-7252-be6e-6e408eb5a4cb | AF9: =IFERROR(__xludf.DUMMYFUNCTION("""COMPUTED_VALUE"""),46189.468923611115) -> 46189.469 | AG9: =IFERROR(__xludf.DUMMYFUNCTION("""COMPUTED_VALUE"""),"credit") -> credit | AH9: =IFERROR(__xludf.DUMMYFUNCTION("""COMPUTED_VALUE"""),20918.18) -> 20918.18 | AI9: =IFERROR(__xludf.DUMMYFUNCTION("""COMPUTED_VALUE"""),"cash_isa") -> cash_isa | AJ9: =IFERROR(__xludf.DUMMYFUNCTION("""COMPUTED_VALUE"""),"9bc00e6b-ce5f-48c5-ae3a-1baabe00f337") -> 9bc00e6b-ce5f-48c5-ae3a-1baabe00f337 | AK9: =IFERROR(__xludf.DUMMYFUNCTION("""COMPUTED_VALUE"""),"a7a2dae7-bd10-44fc-9b1b-25271dcf0442") -> a7a2dae7-bd10-44fc-9b1b-25271dcf0442 | AL9: =IFERROR(__xludf.DUMMYFUNCTION("""COMPUTED_VALUE"""),"a7a2dae7-bd10-44fc-9b1b-25271dcf0442") -> a7a2dae7-bd10-44fc-9b1b-25271dcf0442 | AM9: =IFERROR(__xludf.DUMMYFUNCTION("""COMPUTED_VALUE"""),"JX825895D-940686763") -> JX825895D-940686763 | AN9: =IFERROR(__xludf.DUMMYFUNCTION("""COMPUTED_VALUE"""),20918.18) -> 20918.18 | AO9: =IFERROR(__xludf.DUMMYFUNCTION("""COMPUTED_VALUE"""),"payin") -> payin | AP9: =IFERROR(__xludf.DUMMYFUNCTION("""COMPUTED_VALUE"""),46188.6688425926) -> 46188.669 | AR9: =ROUND(VALUE(AH9),2)&"_"&TRIM(LOWER(AG9)) -> 20918.18_credit | AS9: =IF(AH9="", "", LET(current_amt, ROUND(VALUE(AH9), 2), current_dir, TRIM(LOWER(AG9)), opposite_dir, IF(current_dir="credit", "debit", "credit"), occ, COUNTIFS($AH$3:AH9, AH9, $AG$3:AG9, AG9), opp_total, COUNTIFS($AH$3:$AH$1000, AH9, $AG$3:$AG$1000, opposite_dir), IF(opp_total >= occ, "DROP", "KEEP"))) -> KEEP | AU9: =IFERROR(__xludf.DUMMYFUNCTION("""COMPUTED_VALUE"""),"73df5aae-f42a-49a0-9d8f-616ca6dbebaa") -> 73df5aae-f42a-49a0-9d8f-616ca6dbebaa | AV9: =IFERROR(__xludf.DUMMYFUNCTION("""COMPUTED_VALUE"""),"019ed015-c5dc-794f-b403-b3a6b5e5bcb3") -> 019ed015-c5dc-794f-b403-b3a6b5e5bcb3 | AW9: =IFERROR(__xludf.DUMMYFUNCTION("""COMPUTED_VALUE"""),46189.45773148148) -> 46189.458 | AX9: =IFERROR(__xludf.DUMMYFUNCTION("""COMPUTED_VALUE"""),"debit") -> debit | AY9: =IFERROR(__xludf.DUMMYFUNCTION("""COMPUTED_VALUE"""),2000.0) -> 2000 | AZ9: =IFERROR(__xludf.DUMMYFUNCTION("""COMPUTED_VALUE"""),"cash_isa") -> cash_isa | BA9: =IFERROR(__xludf.DUMMYFUNCTION("""COMPUTED_VALUE"""),"9bc00e6b-ce5f-48c5-ae3a-1baabe00f337") -> 9bc00e6b-ce5f-48c5-ae3a-1baabe00f337 | BB9: =IFERROR(__xludf.DUMMYFUNCTION("""COMPUTED_VALUE"""),"484d47c0-4ba1-45b5-8762-e933a96e2578") -> 484d47c0-4ba1-45b5-8762-e933a96e2578 | BI9: =IFERROR(__xludf.DUMMYFUNCTION("""COMPUTED_VALUE"""),"73df5aae-f42a-49a0-9d8f-616ca6dbebaa") -> 73df5aae-f42a-49a0-9d8f-616ca6dbebaa | BJ9: =IFERROR(__xludf.DUMMYFUNCTION("""COMPUTED_VALUE"""),"019eb0ad-e1f7-7848-a2f9-cb38e5c86b1d") -> 019eb0ad-e1f7-7848-a2f9-cb38e5c86b1d | BK9: =IFERROR(__xludf.DUMMYFUNCTION("""COMPUTED_VALUE"""),46183.35932870371) -> 46183.359 | BL9: =IFERROR(__xludf.DUMMYFUNCTION("""COMPUTED_VALUE"""),"credit") -> credit | BM9: =IFERROR(__xludf.DUMMYFUNCTION("""COMPUTED_VALUE"""),15963.49) -> 15963.49 | BN9: =IFERROR(__xludf.DUMMYFUNCTION("""COMPUTED_VALUE"""),"lisa") -> lisa | BO9: =IFERROR(__xludf.DUMMYFUNCTION("""COMPUTED_VALUE"""),"b7a59586-5d10-4989-91c2-f2376c7a6ab2") -> b7a59586-5d10-4989-91c2-f2376c7a6ab2 | BP9: =IFERROR(__xludf.DUMMYFUNCTION("""COMPUTED_VALUE"""),"429d3d03-20ce-4949-97bc-52dd443bc473") -> 429d3d03-20ce-4949-97bc-52dd443bc473 | BQ9: =IFERROR(__xludf.DUMMYFUNCTION("""COMPUTED_VALUE"""),"429d3d03-20ce-4949-97bc-52dd443bc473") -> 429d3d03-20ce-4949-97bc-52dd443bc473 | BR9: =IFERROR(__xludf.DUMMYFUNCTION("""COMPUTED_VALUE"""),"NOREF-905760162") -> NOREF-905760162 | BS9: =IFERROR(__xludf.DUMMYFUNCTION("""COMPUTED_VALUE"""),15963.49) -> 15963.49 | BT9: =IFERROR(__xludf.DUMMYFUNCTION("""COMPUTED_VALUE"""),"payin") -> payin | BU9: =IFERROR(__xludf.DUMMYFUNCTION("""COMPUTED_VALUE"""),46181.49357638889) -> 46181.494
A10: 73df5aae-f42a-49a0-9d8f-616ca6dbebaa | B10: 019ecf71-0f39-7517-ba66-2d9a255cf8fb | C10: 46189.333 | D10: credit | E10: 12001.69 | F10: cash_isa | G10: 9bc00e6b-ce5f-48c5-ae3a-1baabe00f337 | H10: 43fda8b1-46b9-42e8-ae27-47e24487252b | AD10: =IFERROR(__xludf.DUMMYFUNCTION("""COMPUTED_VALUE"""),"73df5aae-f42a-49a0-9d8f-616ca6dbebaa") -> 73df5aae-f42a-49a0-9d8f-616ca6dbebaa | AE10: =IFERROR(__xludf.DUMMYFUNCTION("""COMPUTED_VALUE"""),"019ed024-8a33-7fb5-96a0-78ffd98b3516") -> 019ed024-8a33-7fb5-96a0-78ffd98b3516 | AF10: =IFERROR(__xludf.DUMMYFUNCTION("""COMPUTED_VALUE"""),46189.468935185185) -> 46189.469 | AG10: =IFERROR(__xludf.DUMMYFUNCTION("""COMPUTED_VALUE"""),"credit") -> credit | AH10: =IFERROR(__xludf.DUMMYFUNCTION("""COMPUTED_VALUE"""),7.35) -> 7.35 | AI10: =IFERROR(__xludf.DUMMYFUNCTION("""COMPUTED_VALUE"""),"cash_isa") -> cash_isa | AJ10: =IFERROR(__xludf.DUMMYFUNCTION("""COMPUTED_VALUE"""),"9bc00e6b-ce5f-48c5-ae3a-1baabe00f337") -> 9bc00e6b-ce5f-48c5-ae3a-1baabe00f337 | AK10: =IFERROR(__xludf.DUMMYFUNCTION("""COMPUTED_VALUE"""),"42c3a58b-fec1-43e1-b86e-f071b829ba7a") -> 42c3a58b-fec1-43e1-b86e-f071b829ba7a | AL10: =IFERROR(__xludf.DUMMYFUNCTION("""COMPUTED_VALUE"""),"42c3a58b-fec1-43e1-b86e-f071b829ba7a") -> 42c3a58b-fec1-43e1-b86e-f071b829ba7a | AM10: =IFERROR(__xludf.DUMMYFUNCTION("""COMPUTED_VALUE"""),"NOREF-910332414") -> NOREF-910332414 | AN10: =IFERROR(__xludf.DUMMYFUNCTION("""COMPUTED_VALUE"""),7.35) -> 7.35 | AO10: =IFERROR(__xludf.DUMMYFUNCTION("""COMPUTED_VALUE"""),"payin") -> payin | AP10: =IFERROR(__xludf.DUMMYFUNCTION("""COMPUTED_VALUE"""),46188.454293981486) -> 46188.454 | AR10: =ROUND(VALUE(AH10),2)&"_"&TRIM(LOWER(AG10)) -> 7.35_credit | AS10: =IF(AH10="", "", LET(current_amt, ROUND(VALUE(AH10), 2), current_dir, TRIM(LOWER(AG10)), opposite_dir, IF(current_dir="credit", "debit", "credit"), occ, COUNTIFS($AH$3:AH10, AH10, $AG$3:AG10, AG10), opp_total, COUNTIFS($AH$3:$AH$1000, AH10, $AG$3:$AG$1000, opposite_dir), IF(opp_total >= occ, "DROP", "KEEP"))) -> KEEP | AU10: =IFERROR(__xludf.DUMMYFUNCTION("""COMPUTED_VALUE"""),"73df5aae-f42a-49a0-9d8f-616ca6dbebaa") -> 73df5aae-f42a-49a0-9d8f-616ca6dbebaa | AV10: =IFERROR(__xludf.DUMMYFUNCTION("""COMPUTED_VALUE"""),"019ed015-d33d-7f61-8bb3-deadbf0d9c07") -> 019ed015-d33d-7f61-8bb3-deadbf0d9c07 | AW10: =IFERROR(__xludf.DUMMYFUNCTION("""COMPUTED_VALUE"""),46189.457777777774) -> 46189.458 | AX10: =IFERROR(__xludf.DUMMYFUNCTION("""COMPUTED_VALUE"""),"debit") -> debit | AY10: =IFERROR(__xludf.DUMMYFUNCTION("""COMPUTED_VALUE"""),3100.0) -> 3100 | AZ10: =IFERROR(__xludf.DUMMYFUNCTION("""COMPUTED_VALUE"""),"cash_isa") -> cash_isa | BA10: =IFERROR(__xludf.DUMMYFUNCTION("""COMPUTED_VALUE"""),"9bc00e6b-ce5f-48c5-ae3a-1baabe00f337") -> 9bc00e6b-ce5f-48c5-ae3a-1baabe00f337 | BB10: =IFERROR(__xludf.DUMMYFUNCTION("""COMPUTED_VALUE"""),"635da7fc-5835-4ab2-807a-a13c63aab420") -> 635da7fc-5835-4ab2-807a-a13c63aab420 | BI10: =IFERROR(__xludf.DUMMYFUNCTION("""COMPUTED_VALUE"""),"73df5aae-f42a-49a0-9d8f-616ca6dbebaa") -> 73df5aae-f42a-49a0-9d8f-616ca6dbebaa | BJ10: =IFERROR(__xludf.DUMMYFUNCTION("""COMPUTED_VALUE"""),"019eb2b6-0f93-7b2a-8031-39c79ca623c7") -> 019eb2b6-0f93-7b2a-8031-39c79ca623c7 | BK10: =IFERROR(__xludf.DUMMYFUNCTION("""COMPUTED_VALUE"""),46183.753900462965) -> 46183.754 | BL10: =IFERROR(__xludf.DUMMYFUNCTION("""COMPUTED_VALUE"""),"credit") -> credit | BM10: =IFERROR(__xludf.DUMMYFUNCTION("""COMPUTED_VALUE"""),703.22) -> 703.22 | BN10: =IFERROR(__xludf.DUMMYFUNCTION("""COMPUTED_VALUE"""),"lisa") -> lisa | BO10: =IFERROR(__xludf.DUMMYFUNCTION("""COMPUTED_VALUE"""),"b7a59586-5d10-4989-91c2-f2376c7a6ab2") -> b7a59586-5d10-4989-91c2-f2376c7a6ab2 | BP10: =IFERROR(__xludf.DUMMYFUNCTION("""COMPUTED_VALUE"""),"04016f15-a048-4e2f-ab88-ad6abdf6ed72") -> 04016f15-a048-4e2f-ab88-ad6abdf6ed72 | BQ10: =IFERROR(__xludf.DUMMYFUNCTION("""COMPUTED_VALUE"""),"04016f15-a048-4e2f-ab88-ad6abdf6ed72") -> 04016f15-a048-4e2f-ab88-ad6abdf6ed72 | BR10: =IFERROR(__xludf.DUMMYFUNCTION("""COMPUTED_VALUE"""),"FRESCO.21302.GFX.20-45732139") -> FRESCO.21302.GFX.20-45732139 | BS10: =IFERROR(__xludf.DUMMYFUNCTION("""COMPUTED_VALUE"""),703.22) -> 703.22 | BT10: =IFERROR(__xludf.DUMMYFUNCTION("""COMPUTED_VALUE"""),"payin") -> payin | BU10: =IFERROR(__xludf.DUMMYFUNCTION("""COMPUTED_VALUE"""),46182.584872685184) -> 46182.585
A11: 73df5aae-f42a-49a0-9d8f-616ca6dbebaa | B11: 019ecf73-786f-735a-8d04-a5ef897c515a | C11: 46189.335 | D11: debit | E11: 12001.69 | F11: cash_isa | G11: 9bc00e6b-ce5f-48c5-ae3a-1baabe00f337 | H11: 43fda8b1-46b9-42e8-ae27-47e24487252b | AD11: =IFERROR(__xludf.DUMMYFUNCTION("""COMPUTED_VALUE"""),"73df5aae-f42a-49a0-9d8f-616ca6dbebaa") -> 73df5aae-f42a-49a0-9d8f-616ca6dbebaa | AE11: =IFERROR(__xludf.DUMMYFUNCTION("""COMPUTED_VALUE"""),"019ed024-88f1-789c-a803-e90f28c9087e") -> 019ed024-88f1-789c-a803-e90f28c9087e | AF11: =IFERROR(__xludf.DUMMYFUNCTION("""COMPUTED_VALUE"""),46189.468935185185) -> 46189.469 | AG11: =IFERROR(__xludf.DUMMYFUNCTION("""COMPUTED_VALUE"""),"credit") -> credit | AH11: =IFERROR(__xludf.DUMMYFUNCTION("""COMPUTED_VALUE"""),250.0) -> 250 | AI11: =IFERROR(__xludf.DUMMYFUNCTION("""COMPUTED_VALUE"""),"cash_isa") -> cash_isa | AJ11: =IFERROR(__xludf.DUMMYFUNCTION("""COMPUTED_VALUE"""),"9bc00e6b-ce5f-48c5-ae3a-1baabe00f337") -> 9bc00e6b-ce5f-48c5-ae3a-1baabe00f337 | AK11: =IFERROR(__xludf.DUMMYFUNCTION("""COMPUTED_VALUE"""),"5a92f897-6035-4172-9831-90028a8a98c2") -> 5a92f897-6035-4172-9831-90028a8a98c2 | AL11: =IFERROR(__xludf.DUMMYFUNCTION("""COMPUTED_VALUE"""),"5a92f897-6035-4172-9831-90028a8a98c2") -> 5a92f897-6035-4172-9831-90028a8a98c2 | AM11: =IFERROR(__xludf.DUMMYFUNCTION("""COMPUTED_VALUE"""),"JC321715Da-518647334") -> JC321715Da-518647334 | AN11: =IFERROR(__xludf.DUMMYFUNCTION("""COMPUTED_VALUE"""),250.0) -> 250 | AO11: =IFERROR(__xludf.DUMMYFUNCTION("""COMPUTED_VALUE"""),"payin") -> payin | AP11: =IFERROR(__xludf.DUMMYFUNCTION("""COMPUTED_VALUE"""),46188.66883101852) -> 46188.669 | AR11: =ROUND(VALUE(AH11),2)&"_"&TRIM(LOWER(AG11)) -> 250_credit | AS11: =IF(AH11="", "", LET(current_amt, ROUND(VALUE(AH11), 2), current_dir, TRIM(LOWER(AG11)), opposite_dir, IF(current_dir="credit", "debit", "credit"), occ, COUNTIFS($AH$3:AH11, AH11, $AG$3:AG11, AG11), opp_total, COUNTIFS($AH$3:$AH$1000, AH11, $AG$3:$AG$1000, opposite_dir), IF(opp_total >= occ, "DROP", "KEEP"))) -> KEEP | AU11: =IFERROR(__xludf.DUMMYFUNCTION("""COMPUTED_VALUE"""),"73df5aae-f42a-49a0-9d8f-616ca6dbebaa") -> 73df5aae-f42a-49a0-9d8f-616ca6dbebaa | AV11: =IFERROR(__xludf.DUMMYFUNCTION("""COMPUTED_VALUE"""),"019ed024-854b-7377-878e-9bd25cd97072") -> 019ed024-854b-7377-878e-9bd25cd97072 | AW11: =IFERROR(__xludf.DUMMYFUNCTION("""COMPUTED_VALUE"""),46189.468923611115) -> 46189.469 | AX11: =IFERROR(__xludf.DUMMYFUNCTION("""COMPUTED_VALUE"""),"credit") -> credit | AY11: =IFERROR(__xludf.DUMMYFUNCTION("""COMPUTED_VALUE"""),21471.6) -> 21471.6 | AZ11: =IFERROR(__xludf.DUMMYFUNCTION("""COMPUTED_VALUE"""),"cash_isa") -> cash_isa | BA11: =IFERROR(__xludf.DUMMYFUNCTION("""COMPUTED_VALUE"""),"9bc00e6b-ce5f-48c5-ae3a-1baabe00f337") -> 9bc00e6b-ce5f-48c5-ae3a-1baabe00f337 | BB11: =IFERROR(__xludf.DUMMYFUNCTION("""COMPUTED_VALUE"""),"228cd2f5-1ee0-4962-a649-82c9f17961ae") -> 228cd2f5-1ee0-4962-a649-82c9f17961ae | BC11: =IFERROR(__xludf.DUMMYFUNCTION("""COMPUTED_VALUE"""),"228cd2f5-1ee0-4962-a649-82c9f17961ae") -> 228cd2f5-1ee0-4962-a649-82c9f17961ae | BD11: =IFERROR(__xludf.DUMMYFUNCTION("""COMPUTED_VALUE"""),"WK648730Ba-580073357") -> WK648730Ba-580073357 | BE11: =IFERROR(__xludf.DUMMYFUNCTION("""COMPUTED_VALUE"""),21471.6) -> 21471.6 | BF11: =IFERROR(__xludf.DUMMYFUNCTION("""COMPUTED_VALUE"""),"payin") -> payin | BG11: =IFERROR(__xludf.DUMMYFUNCTION("""COMPUTED_VALUE"""),46188.66883101852) -> 46188.669 | BI11: =IFERROR(__xludf.DUMMYFUNCTION("""COMPUTED_VALUE"""),"73df5aae-f42a-49a0-9d8f-616ca6dbebaa") -> 73df5aae-f42a-49a0-9d8f-616ca6dbebaa | BJ11: =IFERROR(__xludf.DUMMYFUNCTION("""COMPUTED_VALUE"""),"019eb6b9-6a8d-73ef-87dc-cb539797754d") -> 019eb6b9-6a8d-73ef-87dc-cb539797754d | BK11: =IFERROR(__xludf.DUMMYFUNCTION("""COMPUTED_VALUE"""),46184.533159722225) -> 46184.533 | BL11: =IFERROR(__xludf.DUMMYFUNCTION("""COMPUTED_VALUE"""),"credit") -> credit | BM11: =IFERROR(__xludf.DUMMYFUNCTION("""COMPUTED_VALUE"""),108.26) -> 108.26 | BN11: =IFERROR(__xludf.DUMMYFUNCTION("""COMPUTED_VALUE"""),"lisa") -> lisa | BO11: =IFERROR(__xludf.DUMMYFUNCTION("""COMPUTED_VALUE"""),"b7a59586-5d10-4989-91c2-f2376c7a6ab2") -> b7a59586-5d10-4989-91c2-f2376c7a6ab2 | BP11: =IFERROR(__xludf.DUMMYFUNCTION("""COMPUTED_VALUE"""),"11ab5e3b-6091-443a-9edf-dd35b41adeb6") -> 11ab5e3b-6091-443a-9edf-dd35b41adeb6 | BQ11: =IFERROR(__xludf.DUMMYFUNCTION("""COMPUTED_VALUE"""),"11ab5e3b-6091-443a-9edf-dd35b41adeb6") -> 11ab5e3b-6091-443a-9edf-dd35b41adeb6 | BR11: =IFERROR(__xludf.DUMMYFUNCTION("""COMPUTED_VALUE"""),"72FEE306a-571949853") -> 72FEE306a-571949853 | BS11: =IFERROR(__xludf.DUMMYFUNCTION("""COMPUTED_VALUE"""),108.26) -> 108.26 | BT11: =IFERROR(__xludf.DUMMYFUNCTION("""COMPUTED_VALUE"""),"payin") -> payin | BU11: =IFERROR(__xludf.DUMMYFUNCTION("""COMPUTED_VALUE"""),46183.39266203703) -> 46183.393
